Workbook

Sheet department
A1: Name | B1: Parent
A2: Medical Record
A3: Registration and billing
A4: Respiratory medicine
A5: Medicine
A6: Paediatrics
A7: Endocrinology
A8: Pulmonary and Critical Care Medicine
A9: Radiation Oncology
A10: Obstetrics and Gynaecology
A11: Otorhinolaryngology (ENT)
A12: Ophthalmology (EYE)
A13: Surgery
... A31: Anatomy

Sheet location
A1: Building | B1: type | C1: description | D1: floor | E1: type | F1: description | G1: Room | H1: type | I1: description | J1: Bed | K1: type | L1: description | M1: department
A2: Dental | B2: building
A3: Academic Block | B3: building | C3: Academic Building | D3: First Floor | E3: level | F3: First floor in Academic Building | G3: Department of Biochemistry | H3: wing | M3: Biochemistry
A4: Academic Block | B4: building | C4: Academic Building | D4: Ground Floor | E4: level | F4: Ground floor in Academic Building | G4: Department of Microbiology | H4: wing | M4: Microbiology
A5: Academic Block | B5: building | C5: Academic Building | D5: Ground Floor | E5: level | F5: Ground floor in Academic Building | G5: Department of Pathology | H5: wing | M5: Pathology
A6: Medicine Block | B6: building | C6: New IPD building | D6: Fourth Floor | E6: level | F6: Fourth floor in Medicine Block New IPD building | G6: Hematology ward | H6: ward | I6: Hematology Ward in New IPD Building | M6: Medicine
A7: Medicine Block | B7: building | C7: New IPD building | D7: Fourth Floor | E7: level | F7: Fourth floor in Medicine Block New IPD building | G7: Hematology ward | H7: ward | I7: Hematology Ward in New IPD Building | J7: BED 1 | K7: bed
A8: Medicine Block | B8: building | C8: New IPD building | D8: Fourth Floor | E8: level | F8: Fourth floor in Medicine Block New IPD building | G8: Hematology ward | H8: ward | I8: Hematology Ward in New IPD Building | J8: BED 2 | K8: bed
A9: Medicine Block | B9: building | C9: New IPD building | D9: Fourth Floor | E9: level | F9: Fourth floor in Medicine Block New IPD building | G9: Hematology ward | H9: ward | I9: Hematology Ward in New IPD Building | J9: BED 3 | K9: bed
A10: Medicine Block | B10: building | C10: New IPD building | D10: Fourth Floor | E10: level | F10: Fourth floor in Medicine Block New IPD building | G10: Hematology ward | H10: ward | I10: Hematology Ward in New IPD Building | J10: BED 4 | K10: bed
A11: Medicine Block | B11: building | C11: New IPD building | D11: Fourth Floor | E11: level | F11: Fourth floor in Medicine Block New IPD building | G11: Female Nephrology Ward | H11: ward | I11: Female Nephrology Ward in New IPD Building | M11: Medicine
A12: Medicine Block | B12: building | C12: New IPD building | D12: Fourth Floor | E12: level | F12: Fourth floor in Medicine Block New IPD building | G12: Female Nephrology Ward | H12: ward | I12: Female Nephrology Ward in New IPD Building | J12: Bed 30 | K12: bed
A13: Medicine Block | B13: building | C13: New IPD building | D13: Fourth Floor | E13: level | F13: Fourth floor in Medicine Block New IPD building | G13: Female Nephrology Ward | H13: ward | I13: Female Nephrology Ward in New IPD Building | J13: Bed 29 | K13: bed
A14: Medicine Block | B14: building | C14: New IPD building | D14: Fourth Floor | E14: level | F14: Fourth floor in Medicine Block New IPD building | G14: Female Nephrology Ward | H14: ward | I14: Female Nephrology Ward in New IPD Building | J14: Bed 28 | K14: bed
A15: Medicine Block | B15: building | C15: New IPD building | D15: Fourth Floor | E15: level | F15: Fourth floor in Medicine Block New IPD building | G15: Female Nephrology Ward | H15: ward | I15: Female Nephrology Ward in New IPD Building | J15: Bed 27 | K15: bed
A16: Medicine Block | B16: building | C16: New IPD building | D16: Fourth Floor | E16: level | F16: Fourth floor in Medicine Block New IPD building | G16: Female Nephrology Ward | H16: ward | I16: Female Nephrology Ward in New IPD Building | J16: Bed 26 | K16: bed
A17: Medicine Block | B17: building | C17: New IPD building | D17: Fourth Floor | E17: level | F17: Fourth floor in Medicine Block New IPD building | G17: Female Nephrology Ward | H17: ward | I17: Female Nephrology Ward in New IPD Building | J17: Bed 25 | K17: bed
A18: Medicine Block | B18: building | C18: New IPD building | D18: Fourth Floor | E18: level | F18: Fourth floor in Medicine Block New IPD building | G18: Female Medicine Ward unit 4 | H18: ward | I18: Female Medicine Ward (unit 3,4) in New IPD Building | J18: Bed 24 | K18: bed
A19: Medicine Block | B19: building | C19: New IPD building | D19: Fourth Floor | E19: level | F19: Fourth floor in Medicine Block New IPD building | G19: Female Medicine Ward unit 4 | H19: ward | I19: Female Medicine Ward (unit 3,4) in New IPD Building | J19: Bed 23 | K19: bed
A20: Medicine Block | B20: building | C20: New IPD building | D20: Fourth Floor | E20: level | F20: Fourth floor in Medicine Block New IPD building | G20: Female Medicine Ward unit 4 | H20: ward | I20: Female Medicine Ward (unit 3,4) in New IPD Building | J20: Bed 22 | K20: bed
A21: Medicine Block | B21: building | C21: New IPD building | D21: Fourth Floor | E21: level | F21: Fourth floor in Medicine Block New IPD building | G21: Female Medicine Ward unit 4 | H21: ward | I21: Female Medicine Ward (unit 3,4) in New IPD Building | J21: Bed 21 | K21: bed
A22: Medicine Block | B22: building | C22: New IPD building | D22: Fourth Floor | E22: level | F22: Fourth floor in Medicine Block New IPD building | G22: Female Medicine Ward unit 4 | H22: ward | I22: Female Medicine Ward (unit 3,4) in New IPD Building | J22: Bed 20 | K22: bed
A23: Medicine Block | B23: building | C23: New IPD building | D23: Fourth Floor | E23: level | F23: Fourth floor in Medicine Block New IPD building | G23: Female Medicine Ward unit 4 | H23: ward | I23: Female Medicine Ward (unit 3,4) in New IPD Building | J23: Bed 19 | K23: bed
... A41: Medicine Block | B41: building | C41: New IPD building | D41: Fourth Floor | E41: level | F41: Fourth floor in Medicine Block New IPD building | G41: Female Medicine Ward unit 3 | H41: ward | I41: Female Medicine Ward (unit 3,4) in New IPD Building | J41: Bed 1 | K41: bed
A42: Medicine Block | B42: building | C42: New IPD building | D42: Third Floor | E42: level | F42: Third floor in Medicine Block New IPD building | G42: Hemato Oncology Ward | H42: ward | I42: Hemato Oncology Ward in New IPD Building | M42: Medicine
A43: Medicine Block | B43: building | C43: New IPD building | D43: Third Floor | E43: level | F43: Third floor in Medicine Block New IPD building | G43: Hemato Oncology Ward | H43: ward | I43: Hemato Oncology Ward in New IPD Building | J43: Bed 8 | K43: bed
A44: Medicine Block | B44: building | C44: New IPD building | D44: Third Floor | E44: level | F44: Third floor in Medicine Block New IPD building | G44: Hemato Oncology Ward | H44: ward | I44: Hemato Oncology Ward in New IPD Building | J44: Bed 7 | K44: bed
A45: Medicine Block | B45: building | C45: New IPD building | D45: Third Floor | E45: level | F45: Third floor in Medicine Block New IPD building | G45: Hemato Oncology Ward | H45: ward | I45: Hemato Oncology Ward in New IPD Building | J45: Bed 6 | K45: bed
A46: Medicine Block | B46: building | C46: New IPD building | D46: Third Floor | E46: level | F46: Third floor in Medicine Block New IPD building | G46: Hemato Oncology Ward | H46: ward | I46: Hemato Oncology Ward in New IPD Building | J46: Bed 5 | K46: bed
A47: Medicine Block | B47: building | C47: New IPD building | D47: Third Floor | E47: level | F47: Third floor in Medicine Block New IPD building | G47: Hemato Oncology Ward | H47: ward | I47: Hemato Oncology Ward in New IPD Building | J47: Bed 4 | K47: bed
A48: Medicine Block | B48: building | C48: New IPD building | D48: Third Floor | E48: level | F48: Third floor in Medicine Block New IPD building | G48: Hemato Oncology Ward | H48: ward | I48: Hemato Oncology Ward in New IPD Building | J48: Bed 3 | K48: bed
A49: Medicine Block | B49: building | C49: New IPD building | D49: Third Floor | E49: level | F49: Third floor in Medicine Block New IPD building | G49: Hemato Oncology Ward | H49: ward | I49: Hemato Oncology Ward in New IPD Building | J49: Bed 2 | K49: bed
A50: Medicine Block | B50: building | C50: New IPD building | D50: Third Floor | E50: level | F50: Third floor in Medicine Block New IPD building | G50: Hemato Oncology Ward | H50: ward | I50: Hemato Oncology Ward in New IPD Building | J50: Bed 1 | K50: bed
A51: Medicine Block | B51: building | C51: New IPD building | D51: Third Floor | E51: level | F51: Third floor in Medicine Block New IPD building | G51: Female Endocrinology Ward | H51: ward | I51: Third Floor in Medicine Block New IPD Building | M51: Endocrinology
A52: Medicine Block | B52: building | C52: New IPD building | D52: Third Floor | E52: level | F52: Third floor in Medicine Block New IPD building | G52: Female Endocrinology Ward | H52: ward | I52: Third Floor in Medicine Block New IPD Building | J52: Bed 30 | K52: bed
A53: Medicine Block | B53: building | C53: New IPD building | D53: Third Floor | E53: level | F53: Third floor in Medicine Block New IPD building | G53: Female Endocrinology Ward | H53: ward | I53: Third Floor in Medicine Block New IPD Building | J53: Bed 29 | K53: bed
A54: Medicine Block | B54: building | C54: New IPD building | D54: Third Floor | E54: level | F54: Third floor in Medicine Block New IPD building | G54: Female Endocrinology Ward | H54: ward | I54: Third Floor in Medicine Block New IPD Building | J54: Bed 28 | K54: bed
A55: Medicine Block | B55: building | C55: New IPD building | D55: Third Floor | E55: level | F55: Third floor in Medicine Block New IPD building | G55: Female Endocrinology Ward | H55: ward | I55: Third Floor in Medicine Block New IPD Building | J55: Bed 27 | K55: bed
A56: Medicine Block | B56: building | C56: New IPD building | D56: Third Floor | E56: level | F56: Third floor in Medicine Block New IPD building | G56: Female Endocrinology Ward | H56: ward | I56: Third Floor in Medicine Block New IPD Building | J56: Bed 26 | K56: bed
A57: Medicine Block | B57: building | C57: New IPD building | D57: Third Floor | E57: level | F57: Third floor in Medicine Block New IPD building | G57: Female Endocrinology Ward | H57: ward | I57: Third Floor in Medicine Block New IPD Building | J57: Bed 25 | K57: bed
...

Sheet specimen_definition
A1: title | B1: slug_value | C1: description | D1: derived_from_uri | E1: type_collected_system | F1: type_collected_code | G1: type_collected_display | H1: collection_system | I1: collection_code | J1: collection_display | K1: is_derived | L1: preference | M1: single_use | N1: requirement | O1: retention_value | P1: retention_unit_system | Q1: retention_unit_code | R1: retention_unit_display | S1: container_description | T1: container_capacity_value | U1: container_capacity_unit_system | V1: container_capacity_unit_code | W1: container_capacity_unit_display | X1: container_minimum_volume_quantity_value | Y1: container_minimum_volume_quantity_unit_system | Z1: container_minimum_volume_quantity_unit_code | AA1: container_minimum_volume_quantity_unit_display | AB1: container_minimum_volume_string | AC1: container_cap_system | AD1: container_cap_code | AE1: container_cap_display | AF1: container_preparation
A2: Whole Blood | B2: whole-blood | C2: Blood specimen containing all cellular and plasma components collected directly from the patient. | E2: http://terminology.hl7.org/CodeSystem/v2-0487 | F2: BLD | G2: Blood | H2: http://snomed.info/sct | I2: 28520004 | J2: Venipuncture for blood test | K2: FALSE | L2: preferred | M2: TRUE | T2: 5 | U2: http://unitsofmeasure.org | V2: mL | W2: milliliter | X2: 2 | Y2: http://unitsofmeasure.org | Z2: mL | AA2: milliliter | AC2: http://terminology.hl7.org/CodeSystem/container-cap | AD2: lavender | AE2: lavender cap
A3: Serum | B3: serum | C3: Liquid portion of blood obtained after coagulation, with clotting factors removed. | E3: http://terminology.hl7.org/CodeSystem/v2-0487 | F3: SER | G3: Serum | H3: http://snomed.info/sct | I3: 22778000 | J3: Venipuncture | K3: FALSE | L3: preferred | M3: TRUE | T3: 5 | U3: http://unitsofmeasure.org | V3: mL | W3: milliliter | X3: 2 | Y3: http://unitsofmeasure.org | Z3: mL | AA3: milliliter | AC3: http://terminology.hl7.org/CodeSystem/container-cap | AD3: red | AE3: red cap
A4: Plasma | B4: plasma | C4: Liquid component of anticoagulated blood containing clotting factors and dissolved proteins | E4: http://terminology.hl7.org/CodeSystem/v2-0487 | F4: PLAS | G4: Plasma | H4: http://snomed.info/sct | I4: 22778000 | J4: Venipuncture | K4: FALSE | L4: preferred | M4: TRUE | T4: 5 | U4: http://unitsofmeasure.org | V4: mL | W4: milliliter | X4: 2 | Y4: http://unitsofmeasure.org | Z4: mL | AA4: milliliter | AC4: http://terminology.hl7.org/CodeSystem/container-cap | AD4: lavender | AE4: lavender cap
A5: Blood Venous | B5: venous-blood | C5: Blood specimen collected from a vein via venipuncture for laboratory analysis. | E5: http://terminology.hl7.org/CodeSystem/v2-0487 | F5: BLDV | G5: Blood venous | H5: http://snomed.info/sct | I5: 28520004 | J5: Venipuncture for blood test | K5: FALSE | L5: preferred | M5: TRUE | T5: 5 | U5: http://unitsofmeasure.org | V5: mL | W5: milliliter | X5: 2 | Y5: http://unitsofmeasure.org | Z5: mL | AA5: milliliter | AC5: http://terminology.hl7.org/CodeSystem/container-cap | AD5: red | AE5: red cap
A6: Sputum | B6: sputum | C6: Respiratory specimen consisting of mucus expectorated from the lower airways for laboratory analysis. | E6: http://terminology.hl7.org/CodeSystem/v2-0487 | F6: SPT | G6: Sputum | H6: http://snomed.info/sct | I6: 386089008 | J6: Collection of coughed sputum | K6: FALSE | L6: preferred | M6: TRUE
A7: Urine | B7: urine | C7: Urine sample collected from a patient for biochemical, microscopic and microbiological examination | E7: http://terminology.hl7.org/CodeSystem/v2-0487 | F7: UR | G7: Urine | H7: http://snomed.info/sct | I7: 73416001 | J7: Urine specimen collection, clean catch, mid stream urine | K7: FALSE | L7: preferred | M7: TRUE
A8: Oral Swab | B8: oral-swab | C8: Specimen collected using a sterile swab from a oral cavity for microbiological or molecular testing. | E8: http://terminology.hl7.org/CodeSystem/v2-0487 | F8: ORH | G8: Other | H8: http://snomed.info/sct | I8: 418622002 | J8: Taking oral swab | K8: FALSE | L8: preferred | M8: TRUE
A9: Stool | B9: stool | C9: Fecal specimen collected for microbiological, parasitological, or biochemical testing | E9: http://terminology.hl7.org/CodeSystem/v2-0487 | F9: STL | G9: Stool | H9: http://snomed.info/sct | I9: 225105004 | J9: Collection of stool specimen | K9: FALSE | L9: preferred | M9: TRUE
A10: Ascitic Fluid | B10: ascitic-fluid | C10: Peritoneal fluid collected from the abdominal cavity for diagnostic laboratory evaluation. | E10: http://terminology.hl7.org/CodeSystem/v2-0487 | F10: FGA | G10: Fluid, Abdomen | H10: http://snomed.info/sct | I10: 89305009 | J10: Abdominal paracentesis | K10: FALSE | L10: preferred | M10: TRUE
A11: Synovial Fluid | B11: synovial-fluid | C11: Joint fluid aspirated from a synovial cavity for analysis of joint disorders | E11: http://terminology.hl7.org/CodeSystem/v2-0487 | F11: SNV | G11: Fluid, synovial (Joint fluid) | H11: http://snomed.info/sct | I11: 90131007 | J11: Arthrocentesis | K11: FALSE | L11: preferred | M11: TRUE
A12: Pleural Fluid | B12: pleural-fluid | C12: Fluid collected from the pleural cavity for laboratory analysis of cells, proteins, microorganisms and biochemical markers to evaluate pleural diseases | E12: http://terminology.hl7.org/CodeSystem/v2-0487 | F12: PLR | G12: Pleural fluid (thoracentesis fluid) | H12: http://snomed.info/sct | I12: 91602002 | J12: Thoracentesis | K12: FALSE | L12: preferred | M12: TRUE
A13: Nasal Swab | B13: nasal-swab | C13: Specimen collected from the nasal cavity using a sterile swab for respiratory pathogen testing | E13: http://terminology.hl7.org/CodeSystem/v2-0487 | F13: NSECR | G13: Secretion, Nasal | H13: http://snomed.info/sct | I13: 312882009 | J13: Taking nasal swab | K13: FALSE | L13: preferred | M13: TRUE
A14: Throat Swab | B14: throat-swab | C14: Specimen collected from the oropharynx using a sterile swab to detect bacterial or viral infections of the throat and upper respiratory tract | E14: http://terminology.hl7.org/CodeSystem/v2-0487 | F14: ORH | G14: Other | H14: http://snomed.info/sct | I14: 312880001 | J14: Taking throat swab | K14: FALSE | L14: preferred | M14: TRUE
A15: Bone marrow | B15: bone-marrow | C15: Bone marrow is a soft, spongy tissue found inside bones, collected as a specimen to evaluate blood cell production and diagnose hematological conditions. | E15: http://terminology.hl7.org/CodeSystem/v2-0487 | F15: MAR | G15: Marrow | H15: http://snomed.info/sct | I15: 49401003 | J15: Bone marrow aspiration procedure | K15: FALSE | L15: preferred | M15: TRUE
A16: Pus | B16: pus-test | C16: Pus is a thick, yellowish or greenish fluid collected from infected tissue, used as a specimen to identify causative organisms and diagnose infections. | E16: http://terminology.hl7.org/CodeSystem/v2-0487 | F16: PUS | G16: Pus | H16: http://snomed.info/sct | I16: 14766002 | J16: Aspiration | K16: FALSE | L16: preferred | M16: TRUE
A17: Skin | B17: skin-test | C17: Skin is the outer protective layer of the body, collected as a specimen (scraping/biopsy) to diagnose infections, dermatological conditions, or other abnormalities. | E17: http://terminology.hl7.org/CodeSystem/v2-0487 | F17: SKN | G17: Skin | H17: http://snomed.info/sct | I17: 386148007 | J17: Slit skin stain method | K17: FALSE | L17: preferred | M17: TRUE
... A48: Pancreatic Fluid | B48: pancreatic-fluid | C48: Secretion from the pancreas, analyzed to assess pancreatic function and detect inflammation or malignancy. | E48: http://terminology.hl7.org/CodeSystem/v2-0487 | F48: PAFL | G48: Pancreatic fluid | H48: http://snomed.info/sct | I48: 788641000 | J48: Fine needle aspiration of lesion of pancreas using endoscopic ultrasonography guidance | K48: FALSE | L48: preferred | M48: TRUE

Sheet Imported_observation
A1: Title | B1: slug_value | C1: description | D1: category | E1: status | F1: code_system | G1: code_value | H1: code_display | I1: permitted_data_type | J1: body_site_system | K1: body_site_code | L1: body_site_display | M1: method_system | N1: method_code | O1: method_display | P1: permitted_unit_system | Q1: permitted_unit_code | R1: permitted_unit_display | S1: derived_from_uri | T1: age_min | U1: age_max | V1: age_op | W1: gender | X1: range_display | Y1: range_min | Z1: range_max
A2: Random Blood Sugar (RBS) | B2: random-blood-sugar-rbs | C2: Measures the level of glucose in the blood | D2: laboratory | E2: active | F2: http://loinc.org | G2: 74774-1 | H2: Glucose [Mass/volume] in Serum, Plasma or Blood | I2: integer | M2: http://snomed.info/sct | N2: 36048009 | O2: Glucose measurement | P2: http://unitsofmeasure.org | Q2: mg/dL | R2: milligram per deciliter | X2: low | Z2: 0
A3: Random Blood Sugar (RBS) | B3: random-blood-sugar-rbs | C3: Measures the level of glucose in the blood | D3: laboratory | E3: active | F3: http://loinc.org | G3: 74774-1 | H3: Glucose [Mass/volume] in Serum, Plasma or Blood | I3: integer | M3: http://snomed.info/sct | N3: 36048009 | O3: Glucose measurement | P3: http://unitsofmeasure.org | Q3: mg/dL | R3: milligram per deciliter | X3: normal | Y3: 0 | Z3: 200
A4: Random Blood Sugar (RBS) | B4: random-blood-sugar-rbs | C4: Measures the level of glucose in the blood | D4: laboratory | E4: active | F4: http://loinc.org | G4: 74774-1 | H4: Glucose [Mass/volume] in Serum, Plasma or Blood | I4: integer | M4: http://snomed.info/sct | N4: 36048009 | O4: Glucose measurement | P4: http://unitsofmeasure.org | Q4: mg/dL | R4: milligram per deciliter | X4: high | Y4: 200
A5: Fasting Blood Sugar (FBS) | B5: fasting-blood-sugar-fbs | C5: Measures the level of glucose in the blood in the fasting state | D5: laboratory | E5: active | F5: http://loinc.org | G5: 1557-8 | H5: Fasting glucose [Mass/volume] in Venous blood | I5: integer | M5: http://snomed.info/sct | N5: 36048009 | O5: Glucose measurement | P5: http://unitsofmeasure.org | Q5: mg/dL | R5: milligram per deciliter | X5: low | Z5: 70
A6: Fasting Blood Sugar (FBS) | B6: fasting-blood-sugar-fbs | C6: Measures the level of glucose in the blood in the fasting state | D6: laboratory | E6: active | F6: http://loinc.org | G6: 1557-8 | H6: Fasting glucose [Mass/volume] in Venous blood | I6: integer | M6: http://snomed.info/sct | N6: 36048009 | O6: Glucose measurement | P6: http://unitsofmeasure.org | Q6: mg/dL | R6: milligram per deciliter | X6: normal | Y6: 70 | Z6: 110
A7: Fasting Blood Sugar (FBS) | B7: fasting-blood-sugar-fbs | C7: Measures the level of glucose in the blood in the fasting state | D7: laboratory | E7: active | F7: http://loinc.org | G7: 1557-8 | H7: Fasting glucose [Mass/volume] in Venous blood | I7: integer | M7: http://snomed.info/sct | N7: 36048009 | O7: Glucose measurement | P7: http://unitsofmeasure.org | Q7: mg/dL | R7: milligram per deciliter | X7: high | Y7: 110
A8: Post Prandial Blood Sugar (PPBS) | B8: post-prandial-blood-sugar | C8: Measures the level of glucose in the blood after a meal, used to assess how the body processes sugar and to monitor diabetes control | D8: laboratory | E8: active | F8: http://loinc.org | G8: 87422-2 | H8: Glucose [Mass/volume] in Blood – Post meal | I8: integer | M8: http://snomed.info/sct | N8: 302788006 | O8: Post-prandial blood glucose measurement | P8: http://unitsofmeasure.org | Q8: mg/dL | R8: milligram per deciliter | X8: low | Z8: 0
A9: Post Prandial Blood Sugar (PPBS) | B9: post-prandial-blood-sugar | C9: Measures the level of glucose in the blood after a meal, used to assess how the body processes sugar and to monitor diabetes control | D9: laboratory | E9: active | F9: http://loinc.org | G9: 87422-2 | H9: Glucose [Mass/volume] in Blood – Post meal | I9: integer | M9: http://snomed.info/sct | N9: 302788006 | O9: Post-prandial blood glucose measurement | P9: http://unitsofmeasure.org | Q9: mg/dL | R9: milligram per deciliter | X9: normal | Y9: 0 | Z9: 200
A10: Post Prandial Blood Sugar (PPBS) | B10: post-prandial-blood-sugar | C10: Measures the level of glucose in the blood after a meal, used to assess how the body processes sugar and to monitor diabetes control | D10: laboratory | E10: active | F10: http://loinc.org | G10: 87422-2 | H10: Glucose [Mass/volume] in Blood – Post meal | I10: integer | M10: http://snomed.info/sct | N10: 302788006 | O10: Post-prandial blood glucose measurement | P10: http://unitsofmeasure.org | Q10: mg/dL | R10: milligram per deciliter | X10: high | Y10: 200
A11: Glucose Tolerance test (GTT) | B11: glucose-tolerance-test-gt | C11: Ordered to assess how the body processes glucose and to help diagnose diabetes or gestational diabetes | D11: laboratory | E11: active | F11: http://loinc.org | G11: 21004-7 | H11: Glucose tolerance [Interpretation] in Serum or Plasma | I11: integer | M11: http://snomed.info/sct | N11: 113076002 | O11: Glucose tolerance test (procedure) | P11: http://unitsofmeasure.org | Q11: mg/dL | R11: milligram per deciliter | X11: low | Z11: 0
A12: Glucose Tolerance test (GTT) | B12: glucose-tolerance-test-gt | C12: Ordered to assess how the body processes glucose and to help diagnose diabetes or gestational diabetes | D12: laboratory | E12: active | F12: http://loinc.org | G12: 21004-7 | H12: Glucose tolerance [Interpretation] in Serum or Plasma | I12: integer | M12: http://snomed.info/sct | N12: 113076002 | O12: Glucose tolerance test (procedure) | P12: http://unitsofmeasure.org | Q12: mg/dL | R12: milligram per deciliter | X12: normal | Y12: 0 | Z12: 100
A13: Glucose Tolerance test (GTT) | B13: glucose-tolerance-test-gt | C13: Ordered to assess how the body processes glucose and to help diagnose diabetes or gestational diabetes | D13: laboratory | E13: active | F13: http://loinc.org | G13: 21004-7 | H13: Glucose tolerance [Interpretation] in Serum or Plasma | I13: integer | M13: http://snomed.info/sct | N13: 113076002 | O13: Glucose tolerance test (procedure) | P13: http://unitsofmeasure.org | Q13: mg/dL | R13: milligram per deciliter | X13: high | Y13: 100
A14: Glucose Tolerance test (GTT)-2hrs | B14: glucose-tolerance-test-th | C14: Ordered to assess how the body processes glucose and to help diagnose diabetes or gestational diabetes | D14: laboratory | E14: active | F14: http://loinc.org | G14: 21004-7 | H14: Glucose tolerance [Interpretation] in Serum or Plasma | I14: integer | M14: http://snomed.info/sct | N14: 113076002 | O14: Glucose tolerance test (procedure) | P14: http://unitsofmeasure.org | Q14: mg/dL | R14: milligram per deciliter | X14: low | Z14: 0
A15: Glucose Tolerance test (GTT)-2hrs | B15: glucose-tolerance-test-th | C15: Ordered to assess how the body processes glucose and to help diagnose diabetes or gestational diabetes | D15: laboratory | E15: active | F15: http://loinc.org | G15: 21004-7 | H15: Glucose tolerance [Interpretation] in Serum or Plasma | I15: integer | M15: http://snomed.info/sct | N15: 113076002 | O15: Glucose tolerance test (procedure) | P15: http://unitsofmeasure.org | Q15: mg/dL | R15: milligram per deciliter | X15: normal | Y15: 0 | Z15: 140
A16: Glucose Tolerance test (GTT)-2hrs | B16: glucose-tolerance-test-th | C16: Ordered to assess how the body processes glucose and to help diagnose diabetes or gestational diabetes | D16: laboratory | E16: active | F16: http://loinc.org | G16: 21004-7 | H16: Glucose tolerance [Interpretation] in Serum or Plasma | I16: integer | M16: http://snomed.info/sct | N16: 113076002 | O16: Glucose tolerance test (procedure) | P16: http://unitsofmeasure.org | Q16: mg/dL | R16: milligram per deciliter | X16: high | Y16: 140
A17: Serum Uric acid | B17: serum-uric-acid | C17: Measures uric acid levels in the blood, reflecting purine metabolism | D17: laboratory | E17: active | F17: http://loinc.org | G17: 3084-1 | H17: Urate [Measurement] in Serum or Plasma | I17: decimal | M17: http://snomed.info/sct | N17: 275740009 | O17: Serum Uric acid measurement | P17: http://unitsofmeasure.org | Q17: mg/dL | R17: milligram per deciliter | X17: low | Z17: 2.5
A18: Serum Uric acid | B18: serum-uric-acid | C18: Measures uric acid levels in the blood, reflecting purine metabolism | D18: laboratory | E18: active | F18: http://loinc.org | G18: 3084-1 | H18: Urate [Measurement] in Serum or Plasma | I18: decimal | M18: http://snomed.info/sct | N18: 275740009 | O18: Serum Uric acid measurement | P18: http://unitsofmeasure.org | Q18: mg/dL | R18: milligram per deciliter | X18: normal | Y18: 2.5 | Z18: 7.5
A19: Serum Uric acid | B19: serum-uric-acid | C19: Measures uric acid levels in the blood, reflecting purine metabolism | D19: laboratory | E19: active | F19: http://loinc.org | G19: 3084-1 | H19: Urate [Measurement] in Serum or Plasma | I19: decimal | M19: http://snomed.info/sct | N19: 275740009 | O19: Serum Uric acid measurement | P19: http://unitsofmeasure.org | Q19: mg/dL | R19: milligram per deciliter | X19: high | Y19: 7.5
A20: Serum Calcium | B20: serum-calcium | C20: Measures total calcium in the blood, essential for bone health, nerve signals, and muscle function | D20: laboratory | E20: active | F20: http://loinc.org | G20: 17861-6 | H20: Calcium [Mass/volume] in Serum or Plasma | I20: decimal | M20: http://snomed.info/sct | N20: 271240001 | O20: Serum Calcium measurement | P20: http://unitsofmeasure.org | Q20: mg/dL | R20: milligram per deciliter | X20: low | Z20: 8.4
A21: Serum Calcium | B21: serum-calcium | C21: Measures total calcium in the blood, essential for bone health, nerve signals, and muscle function | D21: laboratory | E21: active | F21: http://loinc.org | G21: 17861-6 | H21: Calcium [Mass/volume] in Serum or Plasma | I21: decimal | M21: http://snomed.info/sct | N21: 271240001 | O21: Serum Calcium measurement | P21: http://unitsofmeasure.org | Q21: mg/dL | R21: milligram per deciliter | X21: normal | Y21: 8.4 | Z21: 10.2
A22: Serum Calcium | B22: serum-calcium | C22: Measures total calcium in the blood, essential for bone health, nerve signals, and muscle function | D22: laboratory | E22: active | F22: http://loinc.org | G22: 17861-6 | H22: Calcium [Mass/volume] in Serum or Plasma | I22: decimal | M22: http://snomed.info/sct | N22: 271240001 | O22: Serum Calcium measurement | P22: http://unitsofmeasure.org | Q22: mg/dL | R22: milligram per deciliter | X22: high | Y22: 10.2
A23: Serum Amylase | B23: serum-amylase | C23: Measures the level of amylase enzyme in the blood, mainly from the pancreas and salivary glands. | D23: laboratory | E23: active | F23: http://loinc.org | G23: 1798-8 | H23: Amylase [Enzymatic activity/volume] in Serum or Plasma | I23: integer | M23: http://snomed.info/sct | N23: 89659001 | O23: Amylase measurement, serum | P23: http://unitsofmeasure.org | Q23: U/L | R23: enzyme unit per liter | X23: low | Z23: 30
A24: Serum Amylase | B24: serum-amylase | C24: Measures the level of amylase enzyme in the blood, mainly from the pancreas and salivary glands. | D24: laboratory | E24: active | F24: http://loinc.org | G24: 1798-8 | H24: Amylase [Enzymatic activity/volume] in Serum or Plasma | I24: integer | M24: http://snomed.info/sct | N24: 89659001 | O24: Amylase measurement, serum | P24: http://unitsofmeasure.org | Q24: U/L | R24: enzyme unit per liter | X24: normal | Y24: 30 | Z24: 110
A25: Serum Amylase | B25: serum-amylase | C25: Measures the level of amylase enzyme in the blood, mainly from the pancreas and salivary glands. | D25: laboratory | E25: active | F25: http://loinc.org | G25: 1798-8 | H25: Amylase [Enzymatic activity/volume] in Serum or Plasma | I25: integer | M25: http://snomed.info/sct | N25: 89659001 | O25: Amylase measurement, serum | P25: http://unitsofmeasure.org | Q25: U/L | R25: enzyme unit per liter | X25: high | Y25: 110
A26: Serum Lipase | B26: serum-lipase | C26: Measures the level of lipase enzyme in the serum, which is primarily produced by the pancreas to break down fats. | D26: laboratory | E26: active | F26: http://loinc.org | G26: 3040-3 | H26: Lipase [Enzymatic activity/volume] in Serum or Plasma | I26: integer | M26: http://snomed.info/sct | N26: 271232007 | O26: Serum Lipase Measurement | P26: http://unitsofmeasure.org | Q26: U/L | R26: enzyme unit per liter | X26: low | Z26: 10
A27: Serum Lipase | B27: serum-lipase | C27: Measures the level of lipase enzyme in the serum, which is primarily produced by the pancreas to break down fats. | D27: laboratory | E27: active | F27: http://loinc.org | G27: 3040-3 | H27: Lipase [Enzymatic activity/volume] in Serum or Plasma | I27: integer | M27: http://snomed.info/sct | N27: 271232007 | O27: Serum Lipase Measurement | P27: http://unitsofmeasure.org | Q27: U/L | R27: enzyme unit per liter | X27: normal | Y27: 10 | Z27: 140
A28: Serum Lipase | B28: serum-lipase | C28: Measures the level of lipase enzyme in the serum, which is primarily produced by the pancreas to break down fats. | D28: laboratory | E28: active | F28: http://loinc.org | G28: 3040-3 | H28: Lipase [Enzymatic activity/volume] in Serum or Plasma | I28: integer | M28: http://snomed.info/sct | N28: 271232007 | O28: Serum Lipase Measurement | P28: http://unitsofmeasure.org | Q28: U/L | R28: enzyme unit per liter | X28: high | Y28: 140
A29: Serum LDH | B29: serum-ldh | C29: Measures LDH enzyme levels, which increase with tissue damage in many organs. | D29: laboratory | E29: active | F29: http://loinc.org | G29: 14804-9 | H29: Lactate dehydrogenase [Enzymatic activity/volume] in Serum or Plasma by Lactate to pyruvate reaction | I29: integer | M29: http://snomed.info/sct | N29: 313854008 | O29: Serum Lactate dehydrogenase measurement | P29: http://unitsofmeasure.org | Q29: U/L | R29: enzyme unit per liter | X29: low | Z29: 140
A30: Serum LDH | B30: serum-ldh | C30: Measures LDH enzyme levels, which increase with tissue damage in many organs. | D30: laboratory | E30: active | F30: http://loinc.org | G30: 14804-9 | H30: Lactate dehydrogenase [Enzymatic activity/volume] in Serum or Plasma by Lactate to pyruvate reaction | I30: integer | M30: http://snomed.info/sct | N30: 313854008 | O30: Serum Lactate dehydrogenase measurement | P30: http://unitsofmeasure.org | Q30: U/L | R30: enzyme unit per liter | X30: normal | Y30: 140 | Z30: 280
A31: Serum LDH | B31: serum-ldh | C31: Measures LDH enzyme levels, which increase with tissue damage in many organs. | D31: laboratory | E31: active | F31: http://loinc.org | G31: 14804-9 | H31: Lactate dehydrogenase [Enzymatic activity/volume] in Serum or Plasma by Lactate to pyruvate reaction | I31: integer | M31: http://snomed.info/sct | N31: 313854008 | O31: Serum Lactate dehydrogenase measurement | P31: http://unitsofmeasure.org | Q31: U/L | R31: enzyme unit per liter | X31: high | Y31: 280
A32: Serum Phosphorus | B32: serum-phosphorus | C32: Measures the level of phosphorus (phosphate) in the serum, which plays a key role in bone formation, energy production, and maintaining acid–base balance in the body. | D32: laboratory | E32: active | F32: http://loinc.org | G32: 2777-1 | H32: Phosphate [Mass/volume] in Serum or Plasma | I32: decimal | M32: http://snomed.info/sct | N32: 271241002 | O32: Serum inorganic phosphate measurement (procedure) | P32: http://unitsofmeasure.org | Q32: mg/dL | R32: milligram per deciliter | X32: low | Z32: 2.5
A33: Serum Phosphorus | B33: serum-phosphorus | C33: Measures the level of phosphorus (phosphate) in the serum, which plays a key role in bone formation, energy production, and maintaining acid–base balance in the body. | D33: laboratory | E33: active | F33: http://loinc.org | G33: 2777-1 | H33: Phosphate [Mass/volume] in Serum or Plasma | I33: decimal | M33: http://snomed.info/sct | N33: 271241002 | O33: Serum inorganic phosphate measurement (procedure) | P33: http://unitsofmeasure.org | Q33: mg/dL | R33: milligram per deciliter | X33: normal | Y33: 2.5 | Z33: 4.5
A34: Serum Phosphorus | B34: serum-phosphorus | C34: Measures the level of phosphorus (phosphate) in the serum, which plays a key role in bone formation, energy production, and maintaining acid–base balance in the body. | D34: laboratory | E34: active | F34: http://loinc.org | G34: 2777-1 | H34: Phosphate [Mass/volume] in Serum or Plasma | I34: decimal | M34: http://snomed.info/sct | N34: 271241002 | O34: Serum inorganic phosphate measurement (procedure) | P34: http://unitsofmeasure.org | Q34: mg/dL | R34: milligram per deciliter | X34: high | Y34: 4.5
A35: Serum Bicarbonate | B35: serum-bicarbonate | C35: Measures serum bicarbonate level for acid–base balance. | D35: laboratory | E35: active | F35: http://loinc.org | G35: 1963-8 | H35: Bicarbonate [Moles/volume] in Serum or Plasma | I35: integer | M35: http://snomed.info/sct | N35: 271239003 | O35: Serum bicarbonate measurement (procedure) | P35: http://unitsofmeasure.org | Q35: mmol/L | R35: millimole per liter | X35: low | Z35: 20
A36: Serum Bicarbonate | B36: serum-bicarbonate | C36: Measures serum bicarbonate level for acid–base balance. | D36: laboratory | E36: active | F36: http://loinc.org | G36: 1963-8 | H36: Bicarbonate [Moles/volume] in Serum or Plasma | I36: integer | M36: http://snomed.info/sct | N36: 271239003 | O36: Serum bicarbonate measurement (procedure) | P36: http://unitsofmeasure.org | Q36: mmol/L | R36: millimole per liter | X36: normal | Y36: 20 | Z36: 30
A37: Serum Bicarbonate | B37: serum-bicarbonate | C37: Measures serum bicarbonate level for acid–base balance. | D37: laboratory | E37: active | F37: http://loinc.org | G37: 1963-8 | H37: Bicarbonate [Moles/volume] in Serum or Plasma | I37: integer | M37: http://snomed.info/sct | N37: 271239003 | O37: Serum bicarbonate measurement (procedure) | P37: http://unitsofmeasure.org | Q37: mmol/L | R37: millimole per liter | X37: high | Y37: 30
A38: Blood Urea | B38: blood-urea | C38: Helps detect metabolic and kidney disorders. | D38: laboratory | E38: active | F38: http://loinc.org | G38: 20977-5 | H38: Urea [Mass/volume] in Blood | I38: integer | M38: http://snomed.info/sct | N38: 269858003 | O38: Biochemical evaluation of blood urea/renal function | P38: http://unitsofmeasure.org | Q38: mg/dL | R38: milligram per deciliter | X38: low | Z38: 15
A39: Blood Urea | B39: blood-urea | C39: Helps detect metabolic and kidney disorders. | D39: laboratory | E39: active | F39: http://loinc.org | G39: 20977-5 | H39: Urea [Mass/volume] in Blood | I39: integer | M39: http://snomed.info/sct | N39: 269858003 | O39: Biochemical evaluation of blood urea/renal function | P39: http://unitsofmeasure.org | Q39: mg/dL | R39: milligram per deciliter | X39: normal | Y39: 15 | Z39: 45
A40: Blood Urea | B40: blood-urea | C40: Helps detect metabolic and kidney disorders. | D40: laboratory | E40: active | F40: http://loinc.org | G40: 20977-5 | H40: Urea [Mass/volume] in Blood | I40: integer | M40: http://snomed.info/sct | N40: 269858003 | O40: Biochemical evaluation of blood urea/renal function | P40: http://unitsofmeasure.org | Q40: mg/dL | R40: milligram per deciliter | X40: high | Y40: 45
...

Sheet observation_definition
A1: Title | B1: slug_value | C1: description | D1: category | E1: status | F1: code_system | G1: code_value | H1: code_display | I1: permitted_data_type | J1: body_site_system | K1: body_site_code | L1: body_site_display | M1: method_system | N1: method_code | O1: method_display | P1: permitted_unit_system | Q1: permitted_unit_code | R1: permitted_unit_display | S1: derived_from_uri
A2: Random Blood Sugar (RBS) | B2: random-blood-sugar-rbs | C2: Measures the level of glucose in the blood | D2: laboratory | E2: active | F2: http://loinc.org | G2: 74774-1 | H2: Glucose [Mass/volume] in Serum, Plasma or Blood | I2: integer | M2: http://snomed.info/sct | N2: 36048009 | O2: Glucose measurement | P2: http://unitsofmeasure.org | Q2: mg/dL | R2: milligram per deciliter
A3: Fasting Blood Sugar (FBS) | B3: fasting-blood-sugar-fbs | C3: Measures the level of glucose in the blood in the fasting state | D3: laboratory | E3: active | F3: http://loinc.org | G3: 1557-8 | H3: Fasting glucose [Mass/volume] in Venous blood | I3: integer | M3: http://snomed.info/sct | N3: 36048009 | O3: Glucose measurement | P3: http://unitsofmeasure.org | Q3: mg/dL | R3: milligram per deciliter
A4: Post Prandial Blood Sugar (PPBS) | B4: post-prandial-blood-sugar | C4: Measures the level of glucose in the blood after a meal, used to assess how the body processes sugar and to monitor diabetes control | D4: laboratory | E4: active | F4: http://loinc.org | G4: 87422-2 | H4: Glucose [Mass/volume] in Blood – Post meal | I4: integer | M4: http://snomed.info/sct | N4: 302788006 | O4: Post-prandial blood glucose measurement | P4: http://unitsofmeasure.org | Q4: mg/dL | R4: milligram per deciliter
A5: Glucose Tolerance test (GTT) | B5: glucose-tolerance-test-gt | C5: Ordered to assess how the body processes glucose and to help diagnose diabetes or gestational diabetes | D5: laboratory | E5: active | F5: http://loinc.org | G5: 21004-7 | H5: Glucose tolerance [Interpretation] in Serum or Plasma | I5: integer | M5: http://snomed.info/sct | N5: 113076002 | O5: Glucose tolerance test (procedure) | P5: http://unitsofmeasure.org | Q5: mg/dL | R5: milligram per deciliter
A6: Glucose Tolerance test (GTT)-2hrs | B6: glucose-tolerance-test-th | C6: Ordered to assess how the body processes glucose and to help diagnose diabetes or gestational diabetes | D6: laboratory | E6: active | F6: http://loinc.org | G6: 21004-7 | H6: Glucose tolerance [Interpretation] in Serum or Plasma | I6: integer | M6: http://snomed.info/sct | N6: 113076002 | O6: Glucose tolerance test (procedure) | P6: http://unitsofmeasure.org | Q6: mg/dL | R6: milligram per deciliter
A7: Serum Uric acid | B7: serum-uric-acid | C7: Measures uric acid levels in the blood, reflecting purine metabolism | D7: laboratory | E7: active | F7: http://loinc.org | G7: 3084-1 | H7: Urate [Measurement] in Serum or Plasma | I7: decimal | M7: http://snomed.info/sct | N7: 275740009 | O7: Serum Uric acid measurement | P7: http://unitsofmeasure.org | Q7: mg/dL | R7: milligram per deciliter
A8: Serum Calcium | B8: serum-calcium | C8: Measures total calcium in the blood, essential for bone health, nerve signals, and muscle function | D8: laboratory | E8: active | F8: http://loinc.org | G8: 17861-6 | H8: Calcium [Mass/volume] in Serum or Plasma | I8: decimal | M8: http://snomed.info/sct | N8: 271240001 | O8: Serum Calcium measurement | P8: http://unitsofmeasure.org | Q8: mg/dL | R8: milligram per deciliter
A9: Serum Amylase | B9: serum-amylase | C9: Measures the level of amylase enzyme in the blood, mainly from the pancreas and salivary glands. | D9: laboratory | E9: active | F9: http://loinc.org | G9: 1798-8 | H9: Amylase [Enzymatic activity/volume] in Serum or Plasma | I9: integer | M9: http://snomed.info/sct | N9: 89659001 | O9: Amylase measurement, serum | P9: http://unitsofmeasure.org | Q9: U/L | R9: enzyme unit per liter
A10: Serum Lipase | B10: serum-lipase | C10: Measures the level of lipase enzyme in the serum, which is primarily produced by the pancreas to break down fats. | D10: laboratory | E10: active | F10: http://loinc.org | G10: 3040-3 | H10: Lipase [Enzymatic activity/volume] in Serum or Plasma | I10: integer | M10: http://snomed.info/sct | N10: 271232007 | O10: Serum Lipase Measurement | P10: http://unitsofmeasure.org | Q10: U/L | R10: enzyme unit per liter
A11: Serum LDH | B11: serum-ldh | C11: Measures LDH enzyme levels, which increase with tissue damage in many organs. | D11: laboratory | E11: active | F11: http://loinc.org | G11: 14804-9 | H11: Lactate dehydrogenase [Enzymatic activity/volume] in Serum or Plasma by Lactate to pyruvate reaction | I11: integer | M11: http://snomed.info/sct | N11: 313854008 | O11: Serum Lactate dehydrogenase measurement | P11: http://unitsofmeasure.org | Q11: U/L | R11: enzyme unit per liter
A12: Serum Phosphorus | B12: serum-phosphorus | C12: Measures the level of phosphorus (phosphate) in the serum, which plays a key role in bone formation, energy production, and maintaining acid–base balance in the body. | D12: laboratory | E12: active | F12: http://loinc.org | G12: 2777-1 | H12: Phosphate [Mass/volume] in Serum or Plasma | I12: decimal | M12: http://snomed.info/sct | N12: 271241002 | O12: Serum inorganic phosphate measurement (procedure) | P12: http://unitsofmeasure.org | Q12: mg/dL | R12: milligram per deciliter
A13: Serum Bicarbonate | B13: serum-bicarbonate | C13: Measures serum bicarbonate level for acid–base balance. | D13: laboratory | E13: active | F13: http://loinc.org | G13: 1963-8 | H13: Bicarbonate [Moles/volume] in Serum or Plasma | I13: integer | M13: http://snomed.info/sct | N13: 271239003 | O13: Serum bicarbonate measurement (procedure) | P13: http://unitsofmeasure.org | Q13: mmol/L | R13: millimole per liter
... A21: Troponin - I | B21: troponin-i | C21: Measures cardiac-specific proteins released into the blood when heart muscle is damaged. | D21: laboratory | E21: active | F21: http://loinc.org | G21: 10839-9 | H21: Troponin I.cardiac [Mass/volume] in Serum or Plasma | I21: decimal | M21: http://snomed.info/sct | N21: 121870001 | O21: Troponin I measurement | P21: http://unitsofmeasure.org | Q21: ng/mL | R21: nanograms per milliliter
A22: Serum HBsAg | B22: serum-hbsag | C22: Detects the presence of Hepatitis B surface antigen in the blood. | D22: laboratory | E22: active | F22: http://loinc.org | G22: 5195-3 | H22: Hepatitis B virus surface Ag [Presence] in Serum | I22: boolean | M22: http://snomed.info/sct | N22: 47758006 | O22: Hepatitis B surface antigen measurement | P22: http://unitsofmeasure.org
A23: HCV Antibody Test (Anti HCV) | B23: hcv-antibody-test-anti-hc1 | C23: Screens for antibodies produced in response to Hepatitis C virus infection. | D23: laboratory | E23: active | F23: http://loinc.org | G23: 16128-1 | H23: Hepatitis C virus Ab [Presence] in Serum | I23: boolean | M23: http://snomed.info/sct | N23: 64411004 | O23: Hepatitis C antibody measurement | P23: http://unitsofmeasure.org
A24: Hepatitis A virus Ab (HAV)-Rapid | B24: hepatitis-a-virus-ab-hav | C24: Detects IgM antibodies against Hepatitis A virus, indicating recent or acute infection. | D24: laboratory | E24: active | F24: http://loinc.org | G24: 22314-9 | H24: Hepatitis A virus IgM Ab [Presence] in Serum | I24: boolean | M24: http://snomed.info/sct | N24: 88159009 | O24: Hepatitis A virus antibody, immunoglobulin M type | P24: http://unitsofmeasure.org
A25: Hepatitis E Ab (HEV)-Rapid | B25: hepatitis-e-ab-hev-rapid | C25: Detects IgM antibodies to hepatitis E virus (HEV) in blood using a rapid test method. | D25: laboratory | E25: active | F25: http://loinc.org | G25: 14212-5 | H25: Hepatitis E virus IgM Ab [Presence] in Serum | I25: boolean | M25: http://snomed.info/sct | N25: 401242000 | O25: Hepatitis E immunoglobulin M level | P25: http://unitsofmeasure.org
A26: Widal test | B26: widal-test | C26: Indicates recent or acute hepatitis E infection. | D26: laboratory | E26: active | F26: http://loinc.org | G26: 98211-6 | H26: Salmonella species antibody panel- Serum by agglutination | I26: string | M26: http://snomed.info/sct | N26: 165828002 | O26: Widal test (procedure) | P26: http://unitsofmeasure.org
A27: ASO {titer} | B27: aso-titer | C27: Detects antistreptolysin O (ASO) antibodies. | D27: laboratory | E27: active | F27: http://loinc.org | G27: 5370-2 | H27: Streptolysin O Ab [Units/volume] in Serum or Plasma | I27: integer | M27: http://snomed.info/sct | N27: 82703001 | O27: Antistreptolysin O {titer} (procedure) | P27: http://unitsofmeasure.org | Q27: [IU]/mL | R27: international unit per milliliter
A28: RA factor (Quantitative) | B28: ra-factor-quantitative | C28: Indicates recent streptococcal infection. | D28: laboratory | E28: active | F28: http://loinc.org | G28: 11572-5 | H28: Rheumatoid factor [Units/volume] in Serum or Plasma | I28: integer | M28: http://snomed.info/sct | N28: 10239008 | O28: Rheumatoid factor, quantitative | P28: http://unitsofmeasure.org | Q28: [IU]/mL | R28: international unit per milliliter
A29: CRP (including new born) | B29: crp-including-new-born | C29: Measures C-reactive protein levels in the blood, a marker of inflammation or infection. | D29: laboratory | E29: active | F29: http://loinc.org | G29: 30522-7 | H29: C reactive protein [Mass/volume] in Serum or Plasma by High sensitivity method | I29: integer | M29: http://snomed.info/sct | N29: 55235003 | O29: C-reactive protein measurement | P29: http://unitsofmeasure.org | Q29: mg/L | R29: milligram per deciliter
A30: RPR/VDRL test for Syphilis | B30: rprvdrl-test-for-syphili | C30: A screening test that detects antibodies produced in response to syphilis infection. | D30: laboratory | E30: active | F30: http://loinc.org | G30: 20507-0 | H30: Reagin Ab [Presence] in Serum by RPR | I30: string | M30: http://snomed.info/sct | N30: 19869000 | O30: Rapid Plasma Reagin (RPR) test | P30: http://unitsofmeasure.org
A31: ELISA ANA | B31: elisa-ana | C31: Measure antinuclear antibodies (ANA) in serum using ELISA. Helps screen for autoimmune diseases. | D31: laboratory | E31: active | F31: http://loinc.org | G31: 47383-5 | H31: Nuclear Ab [Presence ] in serum by immunoassay | I31: string | M31: http://snomed.info/sct | N31: 76978006 | O31: Enzyme-linked immunosorbent assay (procedure) | P31: http://unitsofmeasure.org
A32: Dengue Test | B32: dengue-test | C32: Detects dengue virus infection using antigen or antibody-based methods. | D32: laboratory | E32: active | F32: http://loinc.org | G32: 104595-4 | H32: Dengue virus Ab.IgG and IgM and NS1 Ag panel - Serum or Plasma | I32: boolean | M32: http://snomed.info/sct | N32: 399302007 | O32: Polymerase chain reaction test for Dengue virus | P32: http://unitsofmeasure.org
A33: Test for Dengue ELISA | B33: test-for-dengue-elisa | C33: Detects dengue virus infection using antigen or antibody-based methods. | D33: laboratory | E33: active | F33: http://loinc.org | G33: 104595-4 | H33: Dengue virus Ab.IgG and IgM and NS1 Ag panel - Serum or Plasma | I33: boolean | M33: http://snomed.info/sct | N33: 399302007 | O33: Polymerase chain reaction test for Dengue virus | P33: http://unitsofmeasure.org
A34: SARS COV-19 PCR test | B34: sars-cov-19-pcr-test | C34: Detects SARS-CoV-2 RNA using real-time PCR. Used for diagnosis of COVID-19. | D34: laboratory | E34: active | F34: http://loinc.org | G34: 96895-8 | H34: SARS-CoV-2 (COVID-19) lineage [Identifier] in Specimen by Molecular genetics method | I34: boolean | M34: http://snomed.info/sct | N34: 399150003 | O34: Polymerase chain reaction test for severe acute respiratory syndrome | P34: http://unitsofmeasure.org
A35: Scrub typhus Test - ELISA | B35: scrub-typhus-test-elisa | C35: Detects antibodies or antigens associated with Orientia tsutsugamushi, the organism causing scrub typhus. | D35: laboratory | E35: active | F35: http://loinc.org | G35: 33897-0 | H35: Orientia tsutsugamushi IgM Ab [Presence] in Serum or Plasma | I35: boolean | M35: http://snomed.info/sct | N35: 104273003 | O35: Febrile agglutinins measurement, Brucella, Francisella, Murine typhus, Q fever, Rocky Mountain Spotted Fever, scrub typhus | P35: http://unitsofmeasure.org
A36: Respiratory Panels (RT PCR) | B36: respiratory-panels-rt-pcr | C36: Multiplex RT-PCR panel detecting common respiratory pathogens. Used in acute respiratory infections. | D36: laboratory | E36: active | F36: http://loinc.org | G36: 92143-7 | H36: Respiratory pathogens DNA and RNA panel - Respiratory system specimen by NAA with probe detection | I36: boolean | M36: http://snomed.info/sct | N36: 115252004 | O36: Microbiological identification method (procedure) | P36: http://unitsofmeasure.org
A37: Typhoid IgM | B37: typhoid-igm | C37: Detects IgM antibodies specific to Salmonella typhi, indicating recent typhoid infection. | D37: laboratory | E37: active | F37: http://loinc.org | G37: 9674-3 | H37: Salmonella sp IgM Ab | I37: boolean | M37: http://snomed.info/sct | N37: 414464004 | O37: Immunoassay method (procedure) | P37: http://unitsofmeasure.org
A38: Influenza A and B virus with subtypes | B38: influenza-a-and-b-virus-w | C38: Molecular detection of Influenza A and B viral RNA. Used in influenza diagnosis. | D38: laboratory | E38: active | F38: http://loinc.org | G38: 81233-9 | H38: Influenza virus types A and B and subtypes RNA panel - Respiratory system specimen by NAA with probe detection | I38: boolean | M38: http://snomed.info/sct | N38: 118089005 | O38: Influenza A virus and Influenza B virus antigen assay (procedure) | P38: http://unitsofmeasure.org
A39: Respiratory Syncytial Virus (RSV) A and B | B39: respiratory-syncytial | C39: PCR-based detection of RSV subtypes. Used in pediatric and adult respiratory infections. | D39: laboratory | E39: active | F39: http://loinc.org | G39: 72885-7 | H39: Respiratory syncytial virus Ag [Presence] in Nasopharynx by Rapid immunoassay | I39: boolean | M39: http://snomed.info/sct | N39: 122274003 | O39: Respiratory syncytial virus culture (procedure) | P39: http://unitsofmeasure.org
A40: Human Meta Pneumo Virus (HMPV) | B40: human-meta-pneumo-virus | C40: Human metapneumovirus RNA [Presence] in Respiratory system specimen by NAA with probe detection | D40: laboratory | E40: active | F40: http://loinc.org | G40: 92134-6 | H40: Human metapneumovirus RNA [Presence] in Respiratory system specimen by NAA with probe detection | I40: boolean | M40: http://snomed.info/sct | N40: 115252004 | O40: Microbiological identification method (procedure) | P40: http://unitsofmeasure.org
A41: Para influenza virus 1 to 4 | B41: para-influenza-virus-1-to | C41: PCR detection of Parainfluenza virus types 1 to 4. Used in respiratory infection evaluation. | D41: laboratory | E41: active | F41: http://loinc.org | G41: 88890-9 | H41: Parainfluenza virus 1+2+3+4 RNA [Presence] in Nasopharynx by NAA with non-probe detection | I41: boolean | M41: http://snomed.info/sct | N41: 391431008 | O41: Parainfluenza virus antibody level (procedure) | P41: http://unitsofmeasure.org
... A47: HIV test (Antibodies 1 and 2) | B47: hiv-test-antibodies-1-and | C47: HIV test (Antibodies 1 and 2) | D47: laboratory | E47: active | F47: http://loinc.org | G47: 85037-0 | H47: (HIV 1 and 2 Ab and HIV 1 p24 Ag panel - Serum or Plasma by Immunoassay) | I47: boolean | M47: http://snomed.info/sct | N47: 50806003 | O47: Human immunodeficiency virus type 1 antibody confirmatory test | P47: http://unitsofmeasure.org
A48: CD4 count | B48: cd4-count | C48: Measures the number of CD4+ T-lymphocytes in the blood, an important marker of immune function. | D48: laboratory | E48: active | F48: http://loinc.org | G48: 24467-3 | H48: CD3+CD4+ (T4 helper) cells [#/volume] in Blood | I48: integer | M48: http://snomed.info/sct | N48: 313660005 | O48: Absolute CD4 count procedure | P48: http://unitsofmeasure.org | Q48: {cells}/uL | R48: cells per microliter
A49: HCV Antibody Test (Anti HCV) | B49: hcv-antibody-test-anti-hc2 | C49: Screens for antibodies produced in response to Hepatitis C virus infection. | D49: laboratory | E49: active | F49: http://loinc.org | G49: 13955-0 | H49: Hepatitis C virus Ab [Presence] in Serum | I49: boolean | M49: http://snomed.info/sct | N49: 64411004 | O49: Hepatitis C antibody measurement | P49: http://unitsofmeasure.org
A50: Japanese Encephalitis IgM | B50: japanese-encephalitis-igm | C50: Detects IgM antibodies against Japanese Encephalitis virus in blood or cerebrospinal fluid for confirmatory diagnosis. | D50: laboratory | E50: active | F50: http://loinc.org | G50: 60532-9 | H50: Japanese encephalitis virus IgM Ab [{titer}] in Cerebral spinal fluid | I50: boolean | M50: http://snomed.info/sct | N50: 122015000 | O50: Measurement of Japanese encephalitis virus antibody | P50: http://unitsofmeasure.org
A51: IgM for Hepatitis A | B51: igm-for-hepatitis-a | C51: Detects IgM antibodies against Hepatitis A virus, indicating recent or acute infection. | D51: laboratory | E51: active | F51: http://loinc.org | G51: 22314-9 | H51: Hepatitis A virus IgM Ab [Presence] in Serum | I51: boolean | M51: http://snomed.info/sct | N51: 88159009 | O51: Hepatitis A virus antibody, immunoglobulin M type | P51: http://unitsofmeasure.org
A52: IgM for Hepatitis E | B52: igm-for-hepatitis-e | C52: Ordered to detect IgM antibodies against the Hepatitis E virus to confirm recent or acute Hepatitis E infection. | D52: laboratory | E52: active | F52: http://loinc.org | G52: 14212-5 | H52: Hepatitis E virus IgM Ab [Presence] in Serum | I52: boolean | M52: http://snomed.info/sct | N52: 401242000 | O52: Hepatitis E immunoglobulin M level | P52: http://unitsofmeasure.org
...

Sheet observation_components
A1: observation_slug | B1: code_system | C1: code_value | D1: code_display | E1: permitted_data_type | F1: unit_system | G1: unit_code | H1: unit_display | I1: age_min | J1: age_max | K1: age_op | L1: gender | M1: range_display | N1: range_min | O1: range_max
A2: random-blood-sugar-rbs | B2: http://loinc.org | C2: 74774-1 | D2: Glucose [Mass/volume] in Serum, Plasma or Blood | E2: integer | F2: http://unitsofmeasure.org | G2: mg/dL | H2: milligram per deciliter | M2: low | O2: 0
A3: random-blood-sugar-rbs | B3: http://loinc.org | C3: 74774-1 | D3: Glucose [Mass/volume] in Serum, Plasma or Blood | E3: integer | F3: http://unitsofmeasure.org | G3: mg/dL | H3: milligram per deciliter | M3: normal | N3: 0 | O3: 200
A4: random-blood-sugar-rbs | B4: http://loinc.org | C4: 74774-1 | D4: Glucose [Mass/volume] in Serum, Plasma or Blood | E4: integer | F4: http://unitsofmeasure.org | G4: mg/dL | H4: milligram per deciliter | M4: high | N4: 200
A5: fasting-blood-sugar-fbs | B5: http://loinc.org | C5: 1557-8 | D5: Fasting Blood Sugar (FBS) | E5: integer | F5: http://unitsofmeasure.org | G5: mg/dL | H5: milligram per deciliter | M5: low | O5: 70
A6: fasting-blood-sugar-fbs | B6: http://loinc.org | C6: 1557-8 | D6: Fasting Blood Sugar (FBS) | E6: integer | F6: http://unitsofmeasure.org | G6: mg/dL | H6: milligram per deciliter | M6: normal | N6: 70 | O6: 110
A7: fasting-blood-sugar-fbs | B7: http://loinc.org | C7: 1557-8 | D7: Fasting Blood Sugar (FBS) | E7: integer | F7: http://unitsofmeasure.org | G7: mg/dL | H7: milligram per deciliter | M7: high | N7: 110
A8: post-prandial-blood-sugar | B8: http://loinc.org | C8: 87422-2 | D8: Post Prandial Blood Sugar (PPBS) | E8: integer | F8: http://unitsofmeasure.org | G8: mg/dL | H8: milligram per deciliter | M8: low | O8: 0
A9: post-prandial-blood-sugar | B9: http://loinc.org | C9: 87422-2 | D9: Post Prandial Blood Sugar (PPBS) | E9: integer | F9: http://unitsofmeasure.org | G9: mg/dL | H9: milligram per deciliter | M9: normal | N9: 0 | O9: 200
A10: post-prandial-blood-sugar | B10: http://loinc.org | C10: 87422-2 | D10: Post Prandial Blood Sugar (PPBS) | E10: integer | F10: http://unitsofmeasure.org | G10: mg/dL | H10: milligram per deciliter | M10: high | N10: 200
A11: glucose-tolerance-test-gt | B11: http://loinc.org | C11: 21004-7 | D11: Glucose Tolerance test (GTT) fasting | E11: integer | F11: http://unitsofmeasure.org | G11: mg/dL | H11: milligram per deciliter | M11: low | O11: 0
A12: glucose-tolerance-test-gt | B12: http://loinc.org | C12: 21004-7 | D12: Glucose Tolerance test (GTT) fasting | E12: integer | F12: http://unitsofmeasure.org | G12: mg/dL | H12: milligram per deciliter | M12: normal | N12: 0 | O12: 100
A13: glucose-tolerance-test-gt | B13: http://loinc.org | C13: 21004-7 | D13: Glucose Tolerance test (GTT) fasting | E13: integer | F13: http://unitsofmeasure.org | G13: mg/dL | H13: milligram per deciliter | M13: high | N13: 100
A14: glucose-tolerance-test-th | B14: http://loinc.org | C14: 21004-7 | D14: Glucose Tolerance test (GTT)-2hrs | E14: integer | F14: http://unitsofmeasure.org | G14: mg/dL | H14: milligram per deciliter | M14: low | O14: 0
A15: glucose-tolerance-test-th | B15: http://loinc.org | C15: 21004-7 | D15: Glucose Tolerance test (GTT)-2hrs | E15: integer | F15: http://unitsofmeasure.org | G15: mg/dL | H15: milligram per deciliter | M15: normal | N15: 0 | O15: 140
A16: glucose-tolerance-test-th | B16: http://loinc.org | C16: 21004-7 | D16: Glucose Tolerance test (GTT)-2hrs | E16: integer | F16: http://unitsofmeasure.org | G16: mg/dL | H16: milligram per deciliter | M16: high | N16: 140
A17: serum-uric-acid | B17: http://loinc.org | C17: 3084-1 | D17: Serum Uric acid | E17: decimal | F17: http://unitsofmeasure.org | G17: mg/dL | H17: milligram per deciliter | M17: low | O17: 2.5
A18: serum-uric-acid | B18: http://loinc.org | C18: 3084-1 | D18: Serum Uric acid | E18: decimal | F18: http://unitsofmeasure.org | G18: mg/dL | H18: milligram per deciliter | M18: normal | N18: 2.5 | O18: 7.5
A19: serum-uric-acid | B19: http://loinc.org | C19: 3084-1 | D19: Serum Uric acid | E19: decimal | F19: http://unitsofmeasure.org | G19: mg/dL | H19: milligram per deciliter | M19: high | N19: 7.5
A20: serum-calcium | B20: http://loinc.org | C20: 17861-6 | D20: Serum Calcium | E20: decimal | F20: http://unitsofmeasure.org | G20: mg/dL | H20: milligram per deciliter | M20: low | O20: 8.4
A21: serum-calcium | B21: http://loinc.org | C21: 17861-6 | D21: Serum Calcium | E21: decimal | F21: http://unitsofmeasure.org | G21: mg/dL | H21: milligram per deciliter | M21: normal | N21: 8.4 | O21: 10.2
A22: serum-calcium | B22: http://loinc.org | C22: 17861-6 | D22: Serum Calcium | E22: decimal | F22: http://unitsofmeasure.org | G22: mg/dL | H22: milligram per deciliter | M22: high | N22: 10.2
A23: serum-amylase | B23: http://loinc.org | C23: 1798-8 | D23: Serum Amylase | E23: integer | F23: http://unitsofmeasure.org | G23: U/L | H23: enzyme unit per liter | M23: low | O23: 30
